[
  {
    "cveID": "CVE-2021-28363",
    "cveASSIGNER": "cve@mitre.org",
    "publishedDate": "2021-03-15T18:15Z",
    "lastModifiedDate": "2021-03-23T16:47Z",
    "description": [
      {
        "lang": "en",
        "value": "The urllib3 library 1.26.x before 1.26.4 for Python omits SSL certificate validation in some cases involving HTTPS to HTTPS proxies. The initial connection to the HTTPS proxy (if an SSLContext isn't given via proxy_config) doesn't verify the hostname of the certificate. This means certificates for different servers that still validate properly with the default urllib3 SSLContext will be silently accepted."
      }
    ],
    "references": [
      {
        "url": "https://github.com/urllib3/urllib3/commits/main",
        "name": "https://github.com/urllib3/urllib3/commits/main",
        "refsource": "MISC",
        "tags": [
          "Patch",
          "Third Party Advisory"
        ]
      },
      {
        "url": "https://pypi.org/project/urllib3/1.26.4/",
        "name": "https://pypi.org/project/urllib3/1.26.4/",
        "refsource": "CONFIRM",
        "tags": [
          "Third Party Advisory"
        ]
      },
      {
        "url": "https://github.com/urllib3/urllib3/commit/8d65ea1ecf6e2cdc27d42124e587c1b83a3118b0",
        "name": "https://github.com/urllib3/urllib3/commit/8d65ea1ecf6e2cdc27d42124e587c1b83a3118b0",
        "refsource": "CONFIRM",
        "tags": [
          "Patch",
          "Third Party Advisory"
        ]
      },
      {
        "url": "https://github.com/urllib3/urllib3/security/advisories/GHSA-5phf-pp7p-vc2r",
        "name": "https://github.com/urllib3/urllib3/security/advisories/GHSA-5phf-pp7p-vc2r",
        "refsource": "CONFIRM",
        "tags": [
          "Mitigation",
          "Third Party Advisory"
        ]
      }
    ]
  },
  {
    "cveID": "CVE-2020-26137",
    "cveASSIGNER": "cve@mitre.org",
    "publishedDate": "2020-09-30T18:15Z",
    "lastModifiedDate": "2020-10-14T05:15Z",
    "description": [
      {
        "lang": "en",
        "value": "urllib3 before 1.25.9 allows CRLF injection if the attacker controls the HTTP request method, as demonstrated by inserting CR and LF control characters in the first argument of putrequest(). NOTE: this is similar to CVE-2020-26116."
      }
    ],
    "references": [
      {
        "url": "https://bugs.python.org/issue39603",
        "name": "https://bugs.python.org/issue39603",
        "refsource": "MISC",
        "tags": [
          "Issue Tracking",
          "Vendor Advisory"
        ]
      },
      {
        "url": "https://github.com/urllib3/urllib3/commit/1dd69c5c5982fae7c87a620d487c2ebf7a6b436b",
        "name": "https://github.com/urllib3/urllib3/commit/1dd69c5c5982fae7c87a620d487c2ebf7a6b436b",
        "refsource": "MISC",
        "tags": [
          "Patch",
          "Third Party Advisory"
        ]
      },
      {
        "url": "https://github.com/urllib3/urllib3/pull/1800",
        "name": "https://github.com/urllib3/urllib3/pull/1800",
        "refsource": "MISC",
        "tags": [
          "Patch",
          "Third Party Advisory"
        ]
      },
      {
        "url": "https://usn.ubuntu.com/4570-1/",
        "name": "USN-4570-1",
        "refsource": "UBUNTU",
        "tags": []
      }
    ]
  },
  {
    "cveID": "CVE-2020-7212",
    "cveASSIGNER": "cve@mitre.org",
    "publishedDate": "2020-03-06T20:15Z",
    "lastModifiedDate": "2020-03-09T16:55Z",
    "description": [
      {
        "lang": "en",
        "value": "The _encode_invalid_chars function in util/url.py in the urllib3 library 1.25.2 through 1.25.7 for Python allows a denial of service (CPU consumption) because of an inefficient algorithm. The percent_encodings array contains all matches of percent encodings. It is not deduplicated. For a URL of length N, the size of percent_encodings may be up to O(N). The next step (normalize existing percent-encoded bytes) also takes up to O(N) for each step, so the total time is O(N^2). If percent_encodings were deduplicated, the time to compute _encode_invalid_chars would be O(kN), where k is at most 484 ((10+6*2)^2)."
      }
    ],
    "references": [
      {
        "url": "https://github.com/urllib3/urllib3/blob/master/CHANGES.rst",
        "name": "https://github.com/urllib3/urllib3/blob/master/CHANGES.rst",
        "refsource": "MISC",
        "tags": [
          "Release Notes",
          "Third Party Advisory"
        ]
      },
      {
        "url": "https://pypi.org/project/urllib3/1.25.8/",
        "name": "https://pypi.org/project/urllib3/1.25.8/",
        "refsource": "MISC",
        "tags": [
          "Release Notes",
          "Vendor Advisory"
        ]
      },
      {
        "url": "https://github.com/urllib3/urllib3/commit/a74c9cfbaed9f811e7563cfc3dce894928e0221a",
        "name": "https://github.com/urllib3/urllib3/commit/a74c9cfbaed9f811e7563cfc3dce894928e0221a",
        "refsource": "MISC",
        "tags": [
          "Patch",
          "Third Party Advisory"
        ]
      }
    ]
  },
  {
    "cveID": "CVE-2018-20060",
    "cveASSIGNER": "cve@mitre.org",
    "publishedDate": "2018-12-11T17:29Z",
    "lastModifiedDate": "2019-10-03T00:03Z",
    "description": [
      {
        "lang": "en",
        "value": "urllib3 before version 1.23 does not remove the Authorization HTTP header when following a cross-origin redirect (i.e., a redirect that differs in host, port, or scheme). This can allow for credentials in the Authorization header to be exposed to unintended hosts or transmitted in cleartext."
      }
    ],
    "references": [
      {
        "url": "https://github.com/urllib3/urllib3/pull/1346",
        "name": "https://github.com/urllib3/urllib3/pull/1346",
        "refsource": "MISC",
        "tags": [
          "Third Party Advisory"
        ]
      },
      {
        "url": "https://github.com/urllib3/urllib3/issues/1316",
        "name": "https://github.com/urllib3/urllib3/issues/1316",
        "refsource": "MISC",
        "tags": [
          "Third Party Advisory"
        ]
      },
      {
        "url": "https://github.com/urllib3/urllib3/blob/master/CHANGES.rst",
        "name": "https://github.com/urllib3/urllib3/blob/master/CHANGES.rst",
        "refsource": "MISC",
        "tags": [
          "Release Notes",
          "Third Party Advisory"
        ]
      },
      {
        "url": "https://bugzilla.redhat.com/show_bug.cgi?id=1649153",
        "name": "https://bugzilla.redhat.com/show_bug.cgi?id=1649153",
        "refsource": "MISC",
        "tags": [
          "Issue Tracking",
          "Mitigation",
          "Patch",
          "Third Party Advisory"
        ]
      },
      {
        "url": "https://lists.fedoraproject.org/archives/list/package-announce@lists.fedoraproject.org/message/5SJERZEJDSUYQP7BNBXMBHRHGY26HRZD/",
        "name": "FEDORA-2019-a6c56f9756",
        "refsource": "FEDORA",
        "tags": [
          "Mailing List",
          "Release Notes",
          "Third Party Advisory"
        ]
      },
      {
        "url": "https://lists.fedoraproject.org/archives/list/package-announce@lists.fedoraproject.org/message/XWP36YW3KSVLXDBY3QJKDYEPCIMN3VQZ/",
        "name": "FEDORA-2019-6afaa38e7b",
        "refsource": "FEDORA",
        "tags": [
          "Mailing List",
          "Release Notes",
          "Third Party Advisory"
        ]
      },
      {
        "url": "https://lists.fedoraproject.org/archives/list/package-announce@lists.fedoraproject.org/message/BXLAXHM3Z6DUCXZ7ZXZ2EAYJXWDCZFCT/",
        "name": "FEDORA-2019-8560719e80",
        "refsource": "FEDORA",
        "tags": [
          "Mailing List",
          "Release Notes",
          "Third Party Advisory"
        ]
      },
      {
        "url": "https://usn.ubuntu.com/3990-1/",
        "name": "USN-3990-1",
        "refsource": "UBUNTU",
        "tags": []
      },
      {
        "url": "https://access.redhat.com/errata/RHSA-2019:2272",
        "name": "RHSA-2019:2272",
        "refsource": "REDHAT",
        "tags": []
      },
      {
        "url": "http://lists.opensuse.org/opensuse-security-announce/2019-09/msg00039.html",
        "name": "openSUSE-SU-2019:2131",
        "refsource": "SUSE",
        "tags": []
      }
    ]
  },
  {
    "cveID": "CVE-2019-11324",
    "cveASSIGNER": "cve@mitre.org",
    "publishedDate": "2019-04-18T21:29Z",
    "lastModifiedDate": "2019-09-14T18:15Z",
    "description": [
      {
        "lang": "en",
        "value": "The urllib3 library before 1.24.2 for Python mishandles certain cases where the desired set of CA certificates is different from the OS store of CA certificates, which results in SSL connections succeeding in situations where a verification failure is the correct outcome. This is related to use of the ssl_context, ca_certs, or ca_certs_dir argument."
      }
    ],
    "references": [
      {
        "url": "https://github.com/urllib3/urllib3/compare/a6ec68a...1efadf4",
        "name": "https://github.com/urllib3/urllib3/compare/a6ec68a...1efadf4",
        "refsource": "MISC",
        "tags": [
          "Patch",
          "Third Party Advisory"
        ]
      },
      {
        "url": "http://www.openwall.com/lists/oss-security/2019/04/19/1",
        "name": "[oss-security] 20190418 Re: urllib3: adds system certificates to ssl_context",
        "refsource": "MLIST",
        "tags": [
          "Mailing List",
          "Third Party Advisory"
        ]
      },
      {
        "url": "https://usn.ubuntu.com/3990-1/",
        "name": "USN-3990-1",
        "refsource": "UBUNTU",
        "tags": [
          "Third Party Advisory"
        ]
      },
      {
        "url": "http://lists.opensuse.org/opensuse-security-announce/2019-09/msg00039.html",
        "name": "openSUSE-SU-2019:2131",
        "refsource": "SUSE",
        "tags": []
      },
      {
        "url": "http://lists.opensuse.org/opensuse-security-announce/2019-09/msg00041.html",
        "name": "openSUSE-SU-2019:2133",
        "refsource": "SUSE",
        "tags": []
      },
      {
        "url": "https://access.redhat.com/errata/RHSA-2019:3335",
        "name": "RHSA-2019:3335",
        "refsource": "REDHAT",
        "tags": []
      },
      {
        "url": "https://access.redhat.com/errata/RHSA-2019:3590",
        "name": "RHSA-2019:3590",
        "refsource": "REDHAT",
        "tags": []
      },
      {
        "url": "https://lists.fedoraproject.org/archives/list/package-announce@lists.fedoraproject.org/message/NKGPJLVLVYCL4L4B4G5TIOTVK4BKPG72/",
        "name": "FEDORA-2020-6148c44137",
        "refsource": "FEDORA",
        "tags": []
      },
      {
        "url": "https://lists.fedoraproject.org/archives/list/package-announce@lists.fedoraproject.org/message/XOSA2NT4DUQDBEIWE6O7KKD24XND7TE2/",
        "name": "FEDORA-2020-d0d9ad17d8",
        "refsource": "FEDORA",
        "tags": []
      }
    ]
  },
  {
    "cveID": "CVE-2019-11236",
    "cveASSIGNER": "cve@mitre.org",
    "publishedDate": "2019-04-15T15:29Z",
    "lastModifiedDate": "2019-06-13T04:29Z",
    "description": [
      {
        "lang": "en",
        "value": "In the urllib3 library through 1.24.1 for Python, CRLF injection is possible if the attacker controls the request parameter."
      }
    ],
    "references": [
      {
        "url": "https://github.com/urllib3/urllib3/issues/1553",
        "name": "https://github.com/urllib3/urllib3/issues/1553",
        "refsource": "MISC",
        "tags": [
          "Issue Tracking",
          "Exploit",
          "Third Party Advisory"
        ]
      },
      {
        "url": "https://usn.ubuntu.com/3990-1/",
        "name": "USN-3990-1",
        "refsource": "UBUNTU",
        "tags": []
      },
      {
        "url": "https://lists.fedoraproject.org/archives/list/package-announce@lists.fedoraproject.org/message/TBI45HO533KYHNB5YRO43TBYKA3E3VRL/",
        "name": "FEDORA-2019-20bc611b61",
        "refsource": "FEDORA",
        "tags": []
      },
      {
        "url": "https://lists.fedoraproject.org/archives/list/package-announce@lists.fedoraproject.org/message/R62XGEYPUTXMRHGX5I37EBCGQ5COHGKR/",
        "name": "FEDORA-2019-fbda9f1e49",
        "refsource": "FEDORA",
        "tags": []
      },
      {
        "url": "https://lists.debian.org/debian-lts-announce/2019/06/msg00016.html",
        "name": "[debian-lts-announce] 20190620 [SECURITY] [DLA 1828-1] python-urllib3 security update",
        "refsource": "MLIST",
        "tags": []
      },
      {
        "url": "https://usn.ubuntu.com/3990-2/",
        "name": "USN-3990-2",
        "refsource": "UBUNTU",
        "tags": []
      },
      {
        "url": "https://access.redhat.com/errata/RHSA-2019:2272",
        "name": "RHSA-2019:2272",
        "refsource": "REDHAT",
        "tags": []
      },
      {
        "url": "http://lists.opensuse.org/opensuse-security-announce/2019-09/msg00039.html",
        "name": "openSUSE-SU-2019:2131",
        "refsource": "SUSE",
        "tags": []
      },
      {
        "url": "http://lists.opensuse.org/opensuse-security-announce/2019-09/msg00041.html",
        "name": "openSUSE-SU-2019:2133",
        "refsource": "SUSE",
        "tags": []
      },
      {
        "url": "https://access.redhat.com/errata/RHSA-2019:3335",
        "name": "RHSA-2019:3335",
        "refsource": "REDHAT",
        "tags": []
      },
      {
        "url": "https://access.redhat.com/errata/RHSA-2019:3590",
        "name": "RHSA-2019:3590",
        "refsource": "REDHAT",
        "tags": []
      },
      {
        "url": "https://lists.fedoraproject.org/archives/list/package-announce@lists.fedoraproject.org/message/NKGPJLVLVYCL4L4B4G5TIOTVK4BKPG72/",
        "name": "FEDORA-2020-6148c44137",
        "refsource": "FEDORA",
        "tags": []
      },
      {
        "url": "https://lists.fedoraproject.org/archives/list/package-announce@lists.fedoraproject.org/message/XOSA2NT4DUQDBEIWE6O7KKD24XND7TE2/",
        "name": "FEDORA-2020-d0d9ad17d8",
        "refsource": "FEDORA",
        "tags": []
      }
    ]
  },
  {
    "cveID": "CVE-2016-9015",
    "cveASSIGNER": "cve@mitre.org",
    "publishedDate": "2017-01-11T16:59Z",
    "lastModifiedDate": "2017-01-13T13:09Z",
    "description": [
      {
        "lang": "en",
        "value": "Versions 1.17 and 1.18 of the Python urllib3 library suffer from a vulnerability that can cause them, in certain configurations, to not correctly validate TLS certificates. This places users of the library with those configurations at risk of man-in-the-middle and information leakage attacks. This vulnerability affects users using versions 1.17 and 1.18 of the urllib3 library, who are using the optional PyOpenSSL support for TLS instead of the regular standard library TLS backend, and who are using OpenSSL 1.1.0 via PyOpenSSL. This is an extremely uncommon configuration, so the security impact of this vulnerability is low."
      }
    ],
    "references": [
      {
        "url": "http://www.securityfocus.com/bid/93941",
        "name": "93941",
        "refsource": "BID",
        "tags": [
          "Third Party Advisory",
          "VDB Entry"
        ]
      },
      {
        "url": "http://www.openwall.com/lists/oss-security/2016/10/27/6",
        "name": "[oss-security] 20161027 CVE-2016-9015: Python urllib3 1.17 and 1.18 certificate verification failure",
        "refsource": "MLIST",
        "tags": [
          "Mailing List",
          "Mitigation"
        ]
      }
    ]
  }
]